[0m09:31:44.450068 [debug] [MainThread]: Sending event: {'category': 'dbt', 'action': 'invocation', 'label': 'start', 'context': [<snowplow_tracker.self_describing_json.SelfDescribingJson object at 0x7878bbcbd960>, <snowplow_tracker.self_describing_json.SelfDescribingJson object at 0x7878bcb0a320>, <snowplow_tracker.self_describing_json.SelfDescribingJson object at 0x7878bcb08ca0>]}


============================== 09:31:44.452566 | 7de6aa3b-a16a-41ad-8d01-42a0dc712bb1 ==============================
[0m09:31:44.452566 [info ] [MainThread]: Running with dbt=1.9.2
[0m09:31:44.453209 [debug] [MainThread]: running dbt with arguments {'printer_width': '80', 'indirect_selection': 'eager', 'log_cache_events': 'False', 'write_json': 'True', 'partial_parse': 'True', 'cache_selected_only': 'False', 'warn_error': 'None', 'debug': 'False', 'fail_fast': 'False', 'log_path': 'logs', 'profiles_dir': '/home/vscode/.dbt', 'version_check': 'True', 'use_colors': 'True', 'use_experimental_parser': 'False', 'no_print': 'None', 'quiet': 'False', 'empty': 'None', 'warn_error_options': 'WarnErrorOptions(include=[], exclude=[])', 'invocation_command': 'dbt test -m source:coffee_shop.customer', 'static_parser': 'True', 'log_format': 'default', 'target_path': 'None', 'introspect': 'True', 'send_anonymous_usage_stats': 'True'}
[0m09:31:44.453747 [error] [MainThread]: Encountered an error:
Runtime Error
  No dbt_project.yml found at expected path /workspaces/ae-club-pernilla/dbt_project.yml
  Verify that each entry within packages.yml (and their transitive dependencies) contains a file named dbt_project.yml
  
[0m09:31:44.454752 [debug] [MainThread]: Resource report: {"command_name": "test", "command_success": false, "command_wall_clock_time": 0.05345039, "process_in_blocks": "0", "process_kernel_time": 0.08198, "process_mem_max_rss": "85888", "process_out_blocks": "8", "process_user_time": 1.077739}
[0m09:31:44.455264 [debug] [MainThread]: Command `dbt test` failed at 09:31:44.455146 after 0.05 seconds
[0m09:31:44.455680 [debug] [MainThread]: Sending event: {'category': 'dbt', 'action': 'invocation', 'label': 'end', 'context': [<snowplow_tracker.self_describing_json.SelfDescribingJson object at 0x7878bbcbd960>, <snowplow_tracker.self_describing_json.SelfDescribingJson object at 0x7878bcb0b970>, <snowplow_tracker.self_describing_json.SelfDescribingJson object at 0x7878bcb0bca0>]}
[0m09:31:44.456102 [debug] [MainThread]: Flushing usage events
[0m09:31:44.779104 [debug] [MainThread]: An error was encountered while trying to flush usage events
[0m09:31:48.356373 [debug] [MainThread]: Sending event: {'category': 'dbt', 'action': 'invocation', 'label': 'start', 'context': [<snowplow_tracker.self_describing_json.SelfDescribingJson object at 0x759787081930>, <snowplow_tracker.self_describing_json.SelfDescribingJson object at 0x759787ecfd60>, <snowplow_tracker.self_describing_json.SelfDescribingJson object at 0x759787ecc2b0>]}


============================== 09:31:48.359010 | d97fc4cb-a3a2-4b21-b895-2715a90bc66c ==============================
[0m09:31:48.359010 [info ] [MainThread]: Running with dbt=1.9.2
[0m09:31:48.359694 [debug] [MainThread]: running dbt with arguments {'printer_width': '80', 'indirect_selection': 'eager', 'write_json': 'True', 'log_cache_events': 'False', 'partial_parse': 'True', 'cache_selected_only': 'False', 'profiles_dir': '/home/vscode/.dbt', 'debug': 'False', 'version_check': 'True', 'log_path': 'logs', 'fail_fast': 'False', 'warn_error': 'None', 'use_colors': 'True', 'use_experimental_parser': 'False', 'empty': 'None', 'quiet': 'False', 'no_print': 'None', 'log_format': 'default', 'introspect': 'True', 'warn_error_options': 'WarnErrorOptions(include=[], exclude=[])', 'invocation_command': 'dbt test -m source:coffee_shop.customers', 'target_path': 'None', 'static_parser': 'True', 'send_anonymous_usage_stats': 'True'}
[0m09:31:48.360265 [error] [MainThread]: Encountered an error:
Runtime Error
  No dbt_project.yml found at expected path /workspaces/ae-club-pernilla/dbt_project.yml
  Verify that each entry within packages.yml (and their transitive dependencies) contains a file named dbt_project.yml
  
[0m09:31:48.361286 [debug] [MainThread]: Resource report: {"command_name": "test", "command_success": false, "command_wall_clock_time": 0.067270994, "process_in_blocks": "0", "process_kernel_time": 0.073225, "process_mem_max_rss": "86384", "process_out_blocks": "8", "process_user_time": 1.048225}
[0m09:31:48.361814 [debug] [MainThread]: Command `dbt test` failed at 09:31:48.361704 after 0.07 seconds
[0m09:31:48.362214 [debug] [MainThread]: Sending event: {'category': 'dbt', 'action': 'invocation', 'label': 'end', 'context': [<snowplow_tracker.self_describing_json.SelfDescribingJson object at 0x759787081930>, <snowplow_tracker.self_describing_json.SelfDescribingJson object at 0x759786f3f1c0>, <snowplow_tracker.self_describing_json.SelfDescribingJson object at 0x759787ecf820>]}
[0m09:31:48.362644 [debug] [MainThread]: Flushing usage events
[0m09:31:48.672689 [debug] [MainThread]: An error was encountered while trying to flush usage events
